<robot name="walker">


  <link name="base_link">
    <inertial>
      <origin rpy="1.57079633 0 0" xyz="0 1 0" />
      <mass value="0.01" />
      <inertia ixx="2e-6" ixy="0" ixz="0" iyy="1.85333E-6" iyz="0" izz="1.85333E-6" />
    </inertial>
    <visual>
      <origin rpy="1.57079633 0 0" xyz="0 1 0" />
      <geometry>
        <box size="0.5 0.02 0.02" />
      </geometry>
      <material
        name="">
        <color
          rgba="1 1 1 1" />
      </material>
    </visual>
  </link>

  <link name="left_leg">
    <inertial>
      <origin
        xyz="0.2 0.5 0"
        rpy="0 0 3.14" />
      <mass
        value="5" />
      <inertia
        ixx="4.169270833e-01"
        ixy="0"
        ixz="0"
        iyy="5.208333333e-04"
        iyz="0"
        izz="4.169270833e-01" />
    </inertial>
    <visual>
      <origin
        xyz="0.2 1.5 0"
        rpy="0 0 3.14" />
      <geometry>
        <box size="0.025 1 0.025" />
      </geometry>
      <material
        name="">
        <color
          rgba="1 1 1 1" />
      </material>
    </visual>
  </link>

  <link name="left_foot">
    <inertial>
      <origin
        xyz="-0.0456029481737161 -0.137654254578205 -0.0142090017915342"
        rpy="0 0 0" />
      <mass
        value="0.119532622148783" />
      <inertia
        ixx="8.89125624153188E-05"
        ixy="2.65831102839148E-06"
        ixz="-1.81293250972766E-11"
        iyy="0.000110026906143505"
        iyz="4.68543934728002E-12"
        izz="2.96276011964012E-05" />
    </inertial>
    <visual>
      <origin
        xyz="0.15 1.1 0.333"
        rpy="0 3.14 3.14" />
      <geometry>
        <mesh
          filename="file:///work/duplo_meshes/left_foot_scaled.obj" />
      </geometry>
      <material
        name="">
        <color
          rgba="0.792156862745098 0.819607843137255 0.933333333333333 1" />
      </material>
    </visual>
    <collision>
      <origin
        xyz="0.15 1.1 0.333"
        rpy="0 3.14 3.14" />
      <geometry>
        <mesh
          filename="file:///work/duplo_meshes/left_foot_scaled.obj" />
      </geometry>
      <drake:proximity_properties>
        <drake:rigid_hydroelastic />
        <drake:mu_dynamic value="0.9" />
        <drake:mu_static value="0.9" />
        <drake:hydroelastic_modulus value="5.0e6" />
        <drake:mesh_resolution_hint value="0.1" />
      </drake:proximity_properties>
    </collision>
  </link>

  <link name="left_arm">
    <inertial>
      <origin
        xyz="-0.4 0.75 0"
        rpy="0 0 0" />
      <mass
        value="2.5" />
      <inertia
        ixx="5.227083333e-02"
        ixy="0"
        ixz="0"
        iyy="3.75e-4"
        iyz="0"
        izz="5.227083333e-02" />
    </inertial>
    <visual>
      <origin
        xyz="-0.4 0.75 0"
        rpy="0 0 0" />
      <geometry>
        < box size="0.03 0.5 0.03" />
      </geometry>
      <material
        name="">
        <color
          rgba="1 1 1 1" />
      </material>
    </visual>
  </link>

  <link name="left_batt">
    <inertial>
      <origin
        xyz="-0.4 0.5 0"
        rpy="0 0 0" />
      <mass
        value="5" />
      <inertia
        ixx="0.0003333"
        ixy="0"
        ixz="0"
        iyy="0.0003333"
        iyz="0"
        izz="0.0003333" />
    </inertial>
    <visual>
      <origin
        xyz="-0.4 0.5 0"
        rpy="0 0 0" />
      <geometry>
        <box size="0.1 0.1 0.1" />
      </geometry>
      <material
        name="">
        <color
          rgba="1 1 1 1" />
      </material>
    </visual>
  </link>

  <link name="right_leg">
    <inertial>
      <origin
        xyz="-0.2 0 0"
        rpy="3.14 0 0" />
      <mass
        value="5" />
      <inertia
        ixx="4.169270833e-01"
        ixy="0"
        ixz="0"
        iyy="5.208333333e-04"
        iyz="0"
        izz="4.169270833e-01" />
    </inertial>
    <visual>
      <origin
        xyz="-0.2 0 0"
        rpy="3.14 0 0" />
      <geometry>
        <box size="0.025 1 0.025" />
      </geometry>
      <material
        name="">
        <color
          rgba="1 1 1 1" />
      </material>
    </visual>
  </link>

  <link name="right_foot">
    <inertial>
      <origin
        xyz="-0.0456029481737161 -0.137654254578205 -0.0142090017915342"
        rpy="0 0 0" />
      <mass
        value="0.119532622148783" />
      <inertia
        ixx="8.89125624153188E-05"
        ixy="2.65831102839148E-06"
        ixz="-1.81293250972766E-11"
        iyy="0.000110026906143505"
        iyz="4.68543934728002E-12"
        izz="2.96276011964012E-05" />
    </inertial>
    <visual>
      <origin
        xyz="-0.15 1.1 -0.333"
        rpy="0 0 3.14" />
      <geometry>
        <mesh
          filename="file:///work/duplo_meshes/right_foot_scaled-2.obj" />
      </geometry>
      <material
        name="">
        <color
          rgba="0.792156862745098 0.819607843137255 0.933333333333333 1" />
      </material>
    </visual>
    <collision>
      <origin
        xyz="-0.15 .1 -0.333"
        rpy="0 0 3.14" />
      <geometry>
        <mesh
          filename="file:///work/duplo_meshes/right_foot_scaled-2.obj" />
      </geometry>
      <drake:proximity_properties>
        <drake:rigid_hydroelastic />
        <drake:mu_dynamic value="0.9" />
        <drake:mu_static value="0.9" />
        <drake:hydroelastic_modulus value="5.0e6" />
        <drake:mesh_resolution_hint value="0.1" />
      </drake:proximity_properties>
    </collision>
  </link>

  <link name="right_arm">
    <inertial>
      <origin
        xyz="0.4 0.75 0"
        rpy="0 0 0" />
      <mass
        value="2.5" />
      <inertia
        ixx="5.227083333e-02"
        ixy="0"
        ixz="0"
        iyy="3.75e-4"
        iyz="0"
        izz="5.227083333e-02" />
    </inertial>
    <visual>
      <origin
        xyz="0.4 0.75 0"
        rpy="0 0 0" />
      <geometry>
        < box size="0.03 0.5 0.03" />
      </geometry>
      <material
        name="">
        <color
          rgba="1 1 1 1" />
      </material>
    </visual>
  </link>

  <link name="right_batt">
    <inertial>
      <origin
        xyz="0.4 0.5 0"
        rpy="0 0 0" />
      <mass
        value="5" />
      <inertia
        ixx="0.0003333"
        ixy="0"
        ixz="0"
        iyy="0.0003333"
        iyz="0"
        izz="0.0003333" />
    </inertial>
    <visual>
      <origin
        xyz="0.4 0.5 0"
        rpy="0 0 0" />
      <geometry>
        <box size="0.1 0.1 0.1" />
      </geometry>
      <material
        name="">
        <color
          rgba="1 1 1 1" />
      </material>
    </visual>
  </link>

  <joint name="base_joint" type="fixed">
    <parent link="base_link" />
    <child link="left_leg" />
  </joint>

  <joint name="com_joint" type="fixed">
    <parent link="left_leg" />
    <child link="com_marker" />
  </joint>

  <joint name="hip_joint"
    type="continuous">
    <origin
      xyz="0 0 0"
      rpy="0 0 0" />
    <parent
      link="left_leg" />
    <child
      link="right_leg" />
    <axis
      xyz="0 0 0" />
  </joint>

  <joint name="left_foot_joint"
    type="fixed">
    <origin
      xyz="0 0 0"
      rpy="0 0 0" />
    <parent
      link="left_leg" />
    <child
      link="left_foot" />
    <axis
      xyz="0 0 0" />
  </joint>

  <joint name="left_arm_joint"
    type="fixed">
    <origin
      xyz="0 0 0"
      rpy="0 0 0" />
    <parent
      link="left_leg" />
    <child
      link="left_arm" />
    <axis
      xyz="0 0 0" />
  </joint>

  <joint name="left_batt_joint"
    type="fixed">
    <origin
      xyz="0 0 0"
      rpy="0 0 0" />
    <parent
      link="left_arm" />
    <child
      link="left_batt" />
    <axis
      xyz="0 0 0" />
  </joint>

  <joint name="right_foot_joint"
    type="fixed">
    <origin
      xyz="0 0 0"
      rpy="0 0 0" />
    <parent
      link="right_leg" />
    <child
      link="right_foot" />
    <axis
      xyz="0 0 0" />
  </joint>

  <joint name="right_arm_joint"
    type="fixed">
    <origin
      xyz="0 0 0"
      rpy="0 0 0" />
    <parent
      link="right_leg" />
    <child
      link="right_arm" />
    <axis
      xyz="0 0 0" />
  </joint>

  <joint name="right_batt_joint"
    type="fixed">
    <origin
      xyz="0 0 0"
      rpy="0 0 0" />
    <parent
      link="right_arm" />
    <child
      link="right_batt" />
    <axis
      xyz="0 0 0" />
  </joint>
</robot>