<mujoco model="onshape">
  <option iterations="50" timestep="0.001" solver="PGS" gravity="0 0 -9.81" />

  <compiler angle="radian" meshdir="meshes" eulerseq="zyx" autolimits="true" />

  <default>
    <joint limited="true" damping="0.01" armature="0.01" frictionloss="0.01" />
    <geom condim="4" contype="1" conaffinity="15" friction="0.9 0.2 0.2" solref="0.001 2" />
    <motor ctrllimited="true" />
    <equality solref="0.001 2" />
    <default class="visualgeom">
      <geom material="visualgeom" condim="1" contype="0" conaffinity="0" />
    </default>
  </default>

  <asset>
    <mesh name="left_arm" file="left_arm.stl" />
    <mesh name="right_foot" file="right_foot.stl" />
    <mesh name="right_leg" file="right_leg.stl" />
    <mesh name="right_battery" file="right_battery.stl" />
    <mesh name="right_arm" file="right_arm.stl" />
    <mesh name="left_foot" file="left_foot.stl" />
    <mesh name="left_leg" file="left_leg.stl" />
    <texture name="texplane" type="2d" builtin="checker" rgb1=".0 .0 .0" rgb2=".8 .8 .8" width="100" height="100" />
    <material name="matplane" reflectance="0." texture="texplane" texrepeat="1 1" texuniform="true" />
    <material name="visualgeom" rgba="0.5 0.9 0.2 1" />
  </asset>

  <worldbody>
    <light directional="true" diffuse="0.4 0.4 0.4" specular="0.1 0.1 0.1" pos="0 0 5.0" dir="0 0 -1" castshadow="false" />
    <light directional="true" diffuse="0.6 0.6 0.6" specular="0.2 0.2 0.2" pos="0 0 4" dir="0 0 -1" />
    <geom name="ground" type="plane" pos="0 0 0" size="100 100 0.001" quat="1 0 0 0" material="matplane" condim="3" conaffinity="15" />
    <camera name="fixed" pos="0 -3.0 0.714817" xyaxes="1 0 0 0 0 1" />
    <camera name="track" mode="trackcom" pos="0 -3.0 0.714817" xyaxes="1 0 0 0 0 1" />
    <body name="root" pos="0 0 0.22481700000000002" quat="1 0 0 0">
      <freejoint name="root" />
      <site name="imu" size="0.01" pos="0 0 0" />
      <geom pos="-0.0201886 0.106284 -0.214817" quat="1 0 0 0" type="mesh" mesh="left_arm" contype="1" conaffinity="0" density="0" group="1" class="visualgeom" />
      <geom type="mesh" rgba="" mesh="left_arm" pos="-0.0201886 0.106284 -0.214817" quat="1 0 0 0" />
      <geom pos="0.00427743 0.00314539 -0.169551" quat="1 0 0 0" type="mesh" mesh="right_foot" contype="1" conaffinity="0" density="0" group="1" class="visualgeom" />
      <geom type="mesh" rgba="" mesh="right_foot" pos="0.00427743 0.00314539 -0.169551" quat="1 0 0 0" />
      <geom pos="0.0142774 0.00264539 -0.169551" quat="0.707107 0 0 0.707107" type="mesh" mesh="right_leg" contype="1" conaffinity="0" density="0" group="1" class="visualgeom" />
      <geom type="mesh" rgba="" mesh="right_leg" pos="0.0142774 0.00264539 -0.169551" quat="0.707107 0 0 0.707107" />
      <geom pos="-0.0700042 0.062893 -0.0900255" quat="-0.0616284 0.704416 -0.704416 -0.0616284" type="mesh" mesh="right_battery" contype="1" conaffinity="0" density="0" group="1" class="visualgeom" />
      <geom type="mesh" rgba="" mesh="right_battery" pos="-0.0700042 0.062893 -0.0900255" quat="-0.0616284 0.704416 -0.704416 -0.0616284" />
      <body name="left_leg" pos="-0.0208226 0.0139365 -0.0162078" quat="0.5 -0.5 -0.5 0.5">
        <inertial pos="0.015831 0.0865829 -0.0193168" quat="0.429494 0.898507 -0.0880727 0.0215063" mass="0.413951" diaginertia="0.00218976 0.00159507 0.000895587" />
        <joint name="hip" pos="0 0 0" axis="0 0 1" range="-1.5708 1.5708" actuatorfrcrange="-1 1" />
        <geom pos="0.0924094 0.198961 -0.017434" quat="0.5 0.5 0.5 -0.5" type="mesh" mesh="right_arm" contype="1" conaffinity="0" density="0" group="1" class="visualgeom" />
        <geom type="mesh" rgba="" mesh="right_arm" pos="0.0924094 0.198961 -0.017434" quat="0.5 0.5 0.5 -0.5" />
        <geom pos="-0.00788849 0.0842042 -0.0613817" quat="0.704416 -0.704416 0.0616284 -0.0616284" type="mesh" mesh="right_battery" contype="1" conaffinity="0" density="0" group="1" class="visualgeom" />
        <geom type="mesh" rgba="" mesh="right_battery" pos="-0.00788849 0.0842042 -0.0613817" quat="0.704416 -0.704416 0.0616284 -0.0616284" />
        <geom pos="-0.0107911 0.153343 0.007" quat="0.5 0.5 0.5 -0.5" type="mesh" mesh="left_foot" contype="1" conaffinity="0" density="0" group="1" class="visualgeom" />
        <geom type="mesh" rgba="" mesh="left_foot" pos="-0.0107911 0.153343 0.007" quat="0.5 0.5 0.5 -0.5" />
        <geom pos="-0.0112911 0.153343 0.023" quat="0.707107 0.707107 0 0" type="mesh" mesh="left_leg" contype="1" conaffinity="0" density="0" group="1" class="visualgeom" />
        <geom type="mesh" rgba="" mesh="left_leg" pos="-0.0112911 0.153343 0.023" quat="0.707107 0.707107 0 0" />
      </body>
    </body>
  </worldbody>

  <actuator>
    <motor name="hip" joint="hip" ctrllimited="true" ctrlrange="-1 1" gear="1" />
  </actuator>

  <sensor>
    <actuatorpos name="hip_p" actuator="hip" />
    <actuatorvel name="hip_v" actuator="hip" />
    <actuatorfrc name="hip_f" actuator="hip" noise="0.001" />
    <framequat name="orientation" objtype="site" noise="0.001" objname="imu" />
    <gyro name="angular-velocity" site="imu" noise="0.005" cutoff="34.9" />
  </sensor>
</mujoco>